Q: Do promises swallow exceptions thrown from inner promises if 'catches' are not explicitly invoked?

A: No

source is in example.js
to run the test mocha test.js

